## 错误码

C++ 之前，处理异常的基本手段是“错误码”

```c++
int n = read_data(fd, ...);    // 读取数据
if (n == 0) {
  ...                    // 返回值不太对，适当处理
}
if (errno == EAGAIN) {
  ...                    // 适当处理错误
}
```

**正常的业务逻辑代码与错误处理代码混在了一起**

## 异常

异常是针对错误码的缺陷而设计的

**异常的处理流程是完全独立的**，throw 抛出异常后就可以不用管了，错误处理代码都集中在专门的 catch 块里。这样就彻底分离了业务逻辑与错误逻辑，看起来更清楚。

**异常是绝对不能被忽略的，必须被处理**。如果你有意或者无意不写 catch 捕获异常，那么它会一直向上传播出去，直至找到一个能够处理的 catch 块。如果实在没有，那就会导致程序立即停止运行，明白地提示你发生了错误，而不会“坚持带病工作”。

**异常可以用在错误码无法使用的场合**，这也算是 C++ 的“私人原因”。因为它比 C 语言多了构造 / 析构函数、操作符重载等新特性，有的函数根本就没有返回值，或者返回值无法表示错误，而全局的 `errno` 实在是“太不优雅”了，与 C++ 的理念不符，所以也必须使用异常来报告错误

```c++
try
{
  int n = read_data(fd, ...);    // 读取数据，可能抛出异常
  
  ...                         // do some right thing
}
catch(...)
{
    ...                       // 集中处理各种错误情况
}
```

C++ 已经为处理异常设计了一个配套的异常类型体系，定义在标准库的 <stdexcept> 头文件里。

![img](https://raw.githubusercontent.com/mowang111/image-hosting/master/typora_images/8ba78367ce53d54a393a8963bb62e867.jpg)

如果继承深度超过三层，就说明有点“过度设计”，很明显现在就有这种趋势了。所以，我建议你最好选择上面的第一层或者第二层的某个类型作为基类，不要再加深层次。

你可以从 runtime_error 派生出自己的异常类：

```c++
class my_exception : public std::runtime_error
{
public:
    using this_type     = my_exception;        // 给自己起个别名
    using super_type    = std::runtime_error;  // 给父类也起个别名
public:
    my_exception(const char* msg):            // 构造函数
        super_type(msg)                      // 别名也可以用于构造
    {}  
    my_exception() = default;                // 默认构造函数
   ~my_exception() = default;                // 默认析构函数
private:
    int code = 0;                            // 其他的内部私有数据
};
```

在抛出异常的时候，我建议你最好不要直接用 throw 关键字，而是要封装成一个函数，这和不要直接用 new、delete 关键字是类似的道理——**通过引入一个“中间层”来获得更多的可读性、安全性和灵活性**。

抛异常的函数不会有返回值，所以应该用第 4 节课里的“属性”做编译阶段优化：

```c++
[[noreturn]]                      // 属性标签
void raise(const char* msg)      // 函数封装throw，没有返回值
{
    throw my_exception(msg);     // 抛出异常，也可以有更多的逻辑
}
```

使用 catch 捕获异常的时候也要注意，C++ 允许编写多个 catch 块，捕获不同的异常，再分别处理。但是，**异常只能按照 catch 块在代码里的顺序依次匹配，而不会去找最佳匹配**。

这个特性导致实际开发的时候有点麻烦，特别是当异常类型体系比较复杂的时候，有可能会因为写错了顺序，进入你本不想进的 catch 块。所以，**我建议你最好只用一个 catch 块，绕过这个“坑”**。

写 catch 块就像是写一个标准函数，所以入口参数也应当使用`“const &”`的形式，避免对象拷贝的代价

```c++
try
{
    raise("error occured");     // 函数封装throw，抛出异常
}
catch(const exception& e)      // const &捕获异常，可以用基类
{
    cout << e.what() << endl;  // what()是exception的虚函数
}
```

### function-try

所谓 function-try，就是把整个函数体视为一个大 try 块，而 catch 块放在后面，与函数体同级并列

```c++
void some_function()
try                          // 函数名之后直接写try块
{
    ...
}
catch(...)                   // catch块与函数体同级并列
{
    ...
}
```

我自己总结了几个应当使用异常的判断准则：

1. 不允许被忽略的错误；

2. 极少数情况下才会发生的错误；

3. 严重影响正常流程，很难恢复到正常状态的错误；

4. 无法本地处理，必须“穿透”调用栈，传递到上层才能被处理的错误。

规则听起来可能有点不好理解，我给你举几个例子。

比如说构造函数，如果内部初始化失败，无法创建，那后面的逻辑也就进行不下去了，所以这里就可以用异常来处理。

再比如，读写文件，通常文件系统很少会出错，总会成功，如果用错误码来处理不存在、权限错误等，就显得太啰嗦，这时也应该使用异常。

相反的例子就是 socket 通信。因为网络链路的不稳定因素太多，收发数据失败简直是“家常便饭”。虽然出错的后果很严重，但它出现的频率太高了，使用异常会增加很多的处理成本，为了性能考虑，还是检查错误码重试比较好。

## 保证不抛出异常

noexcept 专门用来修饰函数，告诉编译器：这个函数不会抛出异常。编译器看到 noexcept，就得到了一个“保证”，就可以对函数做优化，不去加那些栈展开的额外代码，消除异常处理的成本。

和 const 一样，noexcept 要放在函数后面：

```c++
void func_noexcept() noexcept            // 声明绝不会抛出异常
{
    cout << "noexcept" << endl;
}
```

不过你要注意，noexcept 只是做出了一个“不可靠的承诺”，不是“强保证”，编译器无法彻底检查它的行为，标记为 noexcept 的函数也有可能抛出异常：

```c++
void func_maybe_noexcept() noexcept          // 声明绝不会抛出异常
{
    throw "Oh My God";                    // 但也可以抛出异常
}
```

![img](https://raw.githubusercontent.com/mowang111/image-hosting/master/typora_images/96a9e2f3c794a3b24df1a49e1ce8c16e.jpg)